Workbook
Name Prestations: #REF!
Name Prestations: 'Facture de procedure'!$H$18:$H$23
Name Prestations: #REF!
Name Prestations: #REF!
Name Prestations: #REF!
Name Prestations: #REF!
Name Prestations: #REF!
Name produits: '[1]Facture de vente'!$H$23:$H$28
Name produits: '[1]Facture de vente'!$H$23:$H$28
Name produits: 'Facture de vente'!$H$23:$H$28
Name produits: '[1]Facture de vente'!$H$23:$H$28
Name produits: '[1]Facture de vente'!$H$23:$H$28
Name produits: '[1]Facture de vente'!$H$23:$H$28
Name produits: #REF!
Name puhtv: '[1]Facture de vente'!$J$23:$J$56
Name puhtv: '[1]Facture de vente'!$J$23:$J$56
Name puhtv: 'Facture de vente'!$J$23:$J$56
Name puhtv: '[1]Facture de vente'!$J$23:$J$56
Name puhtv: '[1]Facture de vente'!$J$23:$J$56
Name puhtv: '[1]Facture de vente'!$J$23:$J$56
Name puhtv: #REF!
Name Quantitesv: '[1]Facture de vente'!$I$23:$I$39
Name Quantitesv: '[1]Facture de vente'!$I$23:$I$39
Name Quantitesv: 'Facture de vente'!$I$23:$I$39
Name Quantitesv: '[1]Facture de vente'!$I$23:$I$39
Name Quantitesv: '[1]Facture de vente'!$I$23:$I$39
Name Quantitesv: '[1]Facture de vente'!$I$23:$I$39
Name Quantitesv: #REF!
Name RECHERCHEV: Lettre2!$K$47
Name RECHERCHEV: LettreN!$K$47
Name RECHERCHEV: LettreT!$K$44
Name Services: 'Facture de procedure'!$H$19:$H$24

Sheet Créances
H4: FT TRADING
H5: 108, Avenue Gallieni | S5: 10000 | T5: =S5*0.09 -> 900
H6: 93140 BONDY | S6: 30000 | T6: =(S6-S5)*0.08 -> 1600 | U6: =T5+T6 -> 2500
S7: 34000 | T7: =(S7-S6)*0.06 -> 240 | U7: =U6+T7 -> 2740
B8: Acheté | C8: Consommé | H8: Monsieur Hikmet AVINCA
A9: PCD | C9: =LARGE(A17:A1064,1) -> 1 | D9: PCD OFFERT - PENALITES POUR NOUS
A10: LR | B10: 0 | C10: ='Lettres Phénix'!C10 -> #NUM!
A13: Code Client : D93110
B14: ETAT DES CREANCES
V15: A FAIRE
A16: NBRE | B16: V/REF | C16: REMIS LE | D16: ANCIENNETE | E16: NOMBRE DE FACTURES | F16: N/REF | G16: DEBITEUR | H16: CREANCE PRINCIPALE | I16: RECOUVRE ET FACTURE | J16: ETAT | K16: CLOTURE | L16: PENALITES | M16: INDEMNITES | N16: TOTAUX PENALITES | O16: Extratction du départements de la colonne E | P16: Transformation de la colonne L en nombre | Q16: CONDITION de calcul de formule 2 :France ou 1 :Export | R16: DONT EN ATTENTE DE FACTURATION | S16: Lieu | T16: Frais de procédure | U16: Recouvré total | V16: Déjà facturé | W16: Total dépuis le début | X16: Commissions
A17: 1 | B17: 1 | C17: 45736 | D17: 5 | E17: 9 | F17: 20250336 | G17: ALFA FOOD FACTORY | H17: 69081.02 | I17: 62000 | J17: Gestion en cours | L17: =((0.15*H17)/12)*D17 -> 4317.5638 | M17: =E17*40 -> 360 | N17: =L17+M17 -> 4677.5638 | O17: =RIGHT(F17,2) -> 36 | P17: =IF(ISNUMBER(O17),O17,VALUE(RIGHT(O17,2)&SUBSTITUTE(O17,RIGHT(O17,2),""))) -> 36 | Q17: =IF(P17=99,1,2) -> 2 | R17: 14000 | S17: AG | T17: 0 | U17: =I17+R17 -> 76000 | V17: =IF(Q17=2,IF(I17<=10000,I17*0.09,IF(I17<=30000,900+(I17-10000)*0.08,IF(I17>30000,2500+(I17-30000)*0.06)))) -> 4420 | W17: =IF(Q17=2,IF(U17<=10000,U17*0.09,IF(U17<=30000,900+(U17-10000)*0.08,IF(U17>30000,2500+(U17-30000)*0.06)))) -> 5260 | X17: =W17-V17 -> 840
L18: =((0.15*H18)/12)*D18 -> 0 | M18: =E18*40 -> 0 | N18: =L18+M18 -> 0 | O18: =RIGHT(F18,2) | P18: =IF(ISNUMBER(O18),O18,VALUE(RIGHT(O18,2)&SUBSTITUTE(O18,RIGHT(O18,2),""))) -> #VALUE! | Q18: =IF(P18=99,1,2) -> #VALUE! | R18: 0 | T18: 0 | U18: =I18+R18 -> 0 | V18: =IF(Q18=2,IF(I18<=10000,I18*0.09,IF(I18<=30000,900+(I18-10000)*0.08,IF(I18>30000,2320+(I18-30000)*0.06)))) -> #VALUE! | W18: =IF(Q18=2,IF(U18<=10000,U18*0.09,IF(U18<=30000,900+(U18-10000)*0.08,IF(U18>30000,2500+(U18-30000)*0.06)))) -> #VALUE! | X18: =W18-V18 -> #VALUE!
L19: =((0.15*H19)/12)*D19 -> 0 | M19: =E19*40 -> 0 | N19: =L19+M19 -> 0 | O19: =RIGHT(F19,2) | P19: =IF(ISNUMBER(O19),O19,VALUE(RIGHT(O19,2)&SUBSTITUTE(O19,RIGHT(O19,2),""))) -> #VALUE! | Q19: =IF(P19=99,1,2) -> #VALUE! | R19: 0 | T19: 0 | U19: =I19+R19 -> 0 | V19: =IF(Q19=2,IF(I19<=10000,I19*0.09,IF(I19<=30000,900+(I19-10000)*0.08,IF(I19>30000,2320+(I19-30000)*0.06)))) -> #VALUE! | W19: =IF(Q19=2,IF(U19<=10000,U19*0.09,IF(U19<=30000,900+(U19-10000)*0.08,IF(U19>30000,2500+(U19-30000)*0.06)))) -> #VALUE! | X19: =W19-V19 -> #VALUE!
L20: =((0.15*H20)/12)*D20 -> 0 | M20: =E20*40 -> 0 | N20: =L20+M20 -> 0 | O20: =RIGHT(F20,2) | P20: =IF(ISNUMBER(O20),O20,VALUE(RIGHT(O20,2)&SUBSTITUTE(O20,RIGHT(O20,2),""))) -> #VALUE! | Q20: =IF(P20=99,1,2) -> #VALUE! | R20: 0 | T20: 0 | U20: =I20+R20 -> 0 | V20: =IF(Q20=2,IF(I20<=10000,I20*0.09,IF(I20<=30000,900+(I20-10000)*0.08,IF(I20>30000,2320+(I20-30000)*0.06)))) -> #VALUE! | W20: =IF(Q20=2,IF(U20<=10000,U20*0.09,IF(U20<=30000,900+(U20-10000)*0.08,IF(U20>30000,2500+(U20-30000)*0.06)))) -> #VALUE! | X20: =W20-V20 -> #VALUE!
L21: =((0.15*H21)/12)*D21 -> 0 | M21: =E21*40 -> 0 | N21: =L21+M21 -> 0 | O21: =RIGHT(F21,2) | P21: =IF(ISNUMBER(O21),O21,VALUE(RIGHT(O21,2)&SUBSTITUTE(O21,RIGHT(O21,2),""))) -> #VALUE! | Q21: =IF(P21=99,1,2) -> #VALUE! | R21: 0 | T21: 0 | U21: =I21+R21 -> 0 | V21: =IF(Q21=2,IF(I21<=10000,I21*0.09,IF(I21<=30000,900+(I21-10000)*0.08,IF(I21>30000,2320+(I21-30000)*0.06)))) -> #VALUE! | W21: =IF(Q21=2,IF(U21<=10000,U21*0.09,IF(U21<=30000,900+(U21-10000)*0.08,IF(U21>30000,2500+(U21-30000)*0.06)))) -> #VALUE! | X21: =W21-V21 -> #VALUE!
L22: =((0.15*H22)/12)*D22 -> 0 | M22: =E22*40 -> 0 | N22: =L22+M22 -> 0 | O22: =RIGHT(F22,2) | P22: =IF(ISNUMBER(O22),O22,VALUE(RIGHT(O22,2)&SUBSTITUTE(O22,RIGHT(O22,2),""))) -> #VALUE! | Q22: =IF(P22=99,1,2) -> #VALUE! | R22: 0 | T22: 0 | U22: =I22+R22 -> 0 | V22: =IF(Q22=2,IF(I22<=10000,I22*0.09,IF(I22<=30000,900+(I22-10000)*0.08,IF(I22>30000,2320+(I22-30000)*0.06)))) -> #VALUE! | W22: =IF(Q22=2,IF(U22<=10000,U22*0.09,IF(U22<=30000,900+(U22-10000)*0.08,IF(U22>30000,2500+(U22-30000)*0.06)))) -> #VALUE! | X22: =W22-V22 -> #VALUE!
L23: =((0.15*H23)/12)*D23 -> 0 | M23: =E23*40 -> 0 | N23: =L23+M23 -> 0 | O23: =RIGHT(F23,2) | P23: =IF(ISNUMBER(O23),O23,VALUE(RIGHT(O23,2)&SUBSTITUTE(O23,RIGHT(O23,2),""))) -> #VALUE! | Q23: =IF(P23=99,1,2) -> #VALUE! | R23: 0 | T23: 0 | U23: =I23+R23 -> 0 | V23: =IF(Q23=2,IF(I23<=10000,I23*0.09,IF(I23<=30000,900+(I23-10000)*0.08,IF(I23>30000,2320+(I23-30000)*0.06)))) -> #VALUE! | W23: =IF(Q23=2,IF(U23<=10000,U23*0.09,IF(U23<=30000,900+(U23-10000)*0.08,IF(U23>30000,2500+(U23-30000)*0.06)))) -> #VALUE! | X23: =W23-V23 -> #VALUE!
L24: =((0.15*H24)/12)*D24 -> 0 | M24: =E24*40 -> 0 | N24: =L24+M24 -> 0 | O24: =RIGHT(F24,2) | P24: =IF(ISNUMBER(O24),O24,VALUE(RIGHT(O24,2)&SUBSTITUTE(O24,RIGHT(O24,2),""))) -> #VALUE! | Q24: =IF(P24=99,1,2) -> #VALUE! | R24: 0 | T24: 0 | U24: =I24+R24 -> 0 | V24: =IF(Q24=2,IF(I24<=10000,I24*0.09,IF(I24<=30000,900+(I24-10000)*0.08,IF(I24>30000,2320+(I24-30000)*0.06)))) -> #VALUE! | W24: =IF(Q24=2,IF(U24<=10000,U24*0.09,IF(U24<=30000,900+(U24-10000)*0.08,IF(U24>30000,2500+(U24-30000)*0.06)))) -> #VALUE! | X24: =W24-V24 -> #VALUE!
I25: 0 | L25: =((0.15*H25)/12)*D25 -> 0 | M25: =E25*40 -> 0 | N25: =L25+M25 -> 0 | O25: =RIGHT(F25,2) | P25: =IF(ISNUMBER(O25),O25,VALUE(RIGHT(O25,2)&SUBSTITUTE(O25,RIGHT(O25,2),""))) -> #VALUE! | Q25: =IF(P25=99,1,2) -> #VALUE! | R25: 0 | T25: 0 | U25: =I25+R25 -> 0 | V25: =IF(Q25=2,IF(I25<=10000,I25*0.09,IF(I25<=30000,900+(I25-10000)*0.08,IF(I25>30000,2320+(I25-30000)*0.06)))) -> #VALUE! | W25: =IF(Q25=2,IF(U25<=10000,U25*0.09,IF(U25<=30000,900+(U25-10000)*0.08,IF(U25>30000,2500+(U25-30000)*0.06)))) -> #VALUE! | X25: =W25-V25 -> #VALUE!
I26: 0 | L26: =((0.15*H26)/12)*D26 -> 0 | M26: =E26*40 -> 0 | N26: =L26+M26 -> 0 | O26: =RIGHT(F26,2) | P26: =IF(ISNUMBER(O26),O26,VALUE(RIGHT(O26,2)&SUBSTITUTE(O26,RIGHT(O26,2),""))) -> #VALUE! | Q26: =IF(P26=99,1,2) -> #VALUE! | R26: 0 | T26: 0 | U26: =I26+R26 -> 0 | V26: =IF(Q26=2,IF(I26<=10000,I26*0.09,IF(I26<=30000,900+(I26-10000)*0.08,IF(I26>30000,2320+(I26-30000)*0.06)))) -> #VALUE! | W26: =IF(Q26=2,IF(U26<=10000,U26*0.09,IF(U26<=30000,900+(U26-10000)*0.08,IF(U26>30000,2500+(U26-30000)*0.06)))) -> #VALUE! | X26: =W26-V26 -> #VALUE!
I27: 0 | L27: =((0.15*H27)/12)*D27 -> 0 | M27: =E27*40 -> 0 | N27: =L27+M27 -> 0 | O27: =RIGHT(F27,2) | P27: =IF(ISNUMBER(O27),O27,VALUE(RIGHT(O27,2)&SUBSTITUTE(O27,RIGHT(O27,2),""))) -> #VALUE! | Q27: =IF(P27=99,1,2) -> #VALUE! | R27: 0 | T27: 0 | U27: =I27+R27 -> 0 | V27: =IF(Q27=2,IF(I27<=10000,I27*0.09,IF(I27<=30000,900+(I27-10000)*0.08,IF(I27>30000,2320+(I27-30000)*0.06)))) -> #VALUE! | W27: =IF(Q27=2,IF(U27<=10000,U27*0.09,IF(U27<=30000,900+(U27-10000)*0.08,IF(U27>30000,2500+(U27-30000)*0.06)))) -> #VALUE! | X27: =W27-V27 -> #VALUE!
I28: 0 | L28: =((0.15*H28)/12)*D28 -> 0 | M28: =E28*40 -> 0 | N28: =L28+M28 -> 0 | O28: =RIGHT(F28,2) | P28: =IF(ISNUMBER(O28),O28,VALUE(RIGHT(O28,2)&SUBSTITUTE(O28,RIGHT(O28,2),""))) -> #VALUE! | Q28: =IF(P28=99,1,2) -> #VALUE! | R28: 0 | T28: 0 | U28: =I28+R28 -> 0 | V28: =IF(Q28=2,IF(I28<=10000,I28*0.09,IF(I28<=30000,900+(I28-10000)*0.08,IF(I28>30000,2320+(I28-30000)*0.06)))) -> #VALUE! | W28: =IF(Q28=2,IF(U28<=10000,U28*0.09,IF(U28<=30000,900+(U28-10000)*0.08,IF(U28>30000,2500+(U28-30000)*0.06)))) -> #VALUE! | X28: =W28-V28 -> #VALUE!
I29: 0 | L29: =((0.15*H29)/12)*D29 -> 0 | M29: =E29*40 -> 0 | N29: =L29+M29 -> 0 | O29: =RIGHT(F29,2) | P29: =IF(ISNUMBER(O29),O29,VALUE(RIGHT(O29,2)&SUBSTITUTE(O29,RIGHT(O29,2),""))) -> #VALUE! | Q29: =IF(P29=99,1,2) -> #VALUE! | R29: 0 | T29: 0 | U29: =I29+R29 -> 0 | V29: =IF(Q29=2,IF(I29<=10000,I29*0.09,IF(I29<=30000,900+(I29-10000)*0.08,IF(I29>30000,2320+(I29-30000)*0.06)))) -> #VALUE! | W29: =IF(Q29=2,IF(U29<=10000,U29*0.09,IF(U29<=30000,900+(U29-10000)*0.08,IF(U29>30000,2500+(U29-30000)*0.06)))) -> #VALUE! | X29: =W29-V29 -> #VALUE!
I30: 0 | L30: =((0.15*H30)/12)*D30 -> 0 | M30: =E30*40 -> 0 | N30: =L30+M30 -> 0 | O30: =RIGHT(F30,2) | P30: =IF(ISNUMBER(O30),O30,VALUE(RIGHT(O30,2)&SUBSTITUTE(O30,RIGHT(O30,2),""))) -> #VALUE! | Q30: =IF(P30=99,1,2) -> #VALUE! | R30: 0 | T30: 0 | U30: =I30+R30 -> 0 | V30: =IF(Q30=2,IF(I30<=10000,I30*0.09,IF(I30<=30000,900+(I30-10000)*0.08,IF(I30>30000,2320+(I30-30000)*0.06)))) -> #VALUE! | W30: =IF(Q30=2,IF(U30<=10000,U30*0.09,IF(U30<=30000,900+(U30-10000)*0.08,IF(U30>30000,2500+(U30-30000)*0.06)))) -> #VALUE! | X30: =W30-V30 -> #VALUE!
I31: 0 | L31: =((0.15*H31)/12)*D31 -> 0 | M31: =E31*40 -> 0 | N31: =L31+M31 -> 0 | O31: =RIGHT(F31,2) | P31: =IF(ISNUMBER(O31),O31,VALUE(RIGHT(O31,2)&SUBSTITUTE(O31,RIGHT(O31,2),""))) -> #VALUE! | Q31: =IF(P31=99,1,2) -> #VALUE! | R31: 0 | T31: 0 | U31: =I31+R31 -> 0 | V31: =IF(Q31=2,IF(I31<=10000,I31*0.09,IF(I31<=30000,900+(I31-10000)*0.08,IF(I31>30000,2320+(I31-30000)*0.06)))) -> #VALUE! | W31: =IF(Q31=2,IF(U31<=10000,U31*0.09,IF(U31<=30000,900+(U31-10000)*0.08,IF(U31>30000,2500+(U31-30000)*0.06)))) -> #VALUE! | X31: =W31-V31 -> #VALUE!
I32: 0 | L32: =((0.15*H32)/12)*D32 -> 0 | M32: =E32*40 -> 0 | N32: =L32+M32 -> 0 | O32: =RIGHT(F32,2) | P32: =IF(ISNUMBER(O32),O32,VALUE(RIGHT(O32,2)&SUBSTITUTE(O32,RIGHT(O32,2),""))) -> #VALUE! | Q32: =IF(P32=99,1,2) -> #VALUE! | R32: 0 | T32: 0 | U32: =I32+R32 -> 0 | V32: =IF(Q32=2,IF(I32<=10000,I32*0.09,IF(I32<=30000,900+(I32-10000)*0.08,IF(I32>30000,2320+(I32-30000)*0.06)))) -> #VALUE! | W32: =IF(Q32=2,IF(U32<=10000,U32*0.09,IF(U32<=30000,900+(U32-10000)*0.08,IF(U32>30000,2500+(U32-30000)*0.06)))) -> #VALUE! | X32: =W32-V32 -> #VALUE!
I33: 0 | L33: =((0.15*H33)/12)*D33 -> 0 | M33: =E33*40 -> 0 | N33: =L33+M33 -> 0 | O33: =RIGHT(F33,2) | P33: =IF(ISNUMBER(O33),O33,VALUE(RIGHT(O33,2)&SUBSTITUTE(O33,RIGHT(O33,2),""))) -> #VALUE! | Q33: =IF(P33=99,1,2) -> #VALUE! | R33: 0 | T33: 0 | U33: =I33+R33 -> 0 | V33: =IF(Q33=2,IF(I33<=10000,I33*0.09,IF(I33<=30000,900+(I33-10000)*0.08,IF(I33>30000,2320+(I33-30000)*0.06)))) -> #VALUE! | W33: =IF(Q33=2,IF(U33<=10000,U33*0.09,IF(U33<=30000,900+(U33-10000)*0.08,IF(U33>30000,2500+(U33-30000)*0.06)))) -> #VALUE! | X33: =W33-V33 -> #VALUE!
I34: 0 | L34: =((0.15*H34)/12)*D34 -> 0 | M34: =E34*40 -> 0 | N34: =L34+M34 -> 0 | O34: =RIGHT(F34,2) | P34: =IF(ISNUMBER(O34),O34,VALUE(RIGHT(O34,2)&SUBSTITUTE(O34,RIGHT(O34,2),""))) -> #VALUE! | Q34: =IF(P34=99,1,2) -> #VALUE! | R34: 0 | T34: 0 | U34: =I34+R34 -> 0 | V34: =IF(Q34=2,IF(I34<=10000,I34*0.09,IF(I34<=30000,900+(I34-10000)*0.08,IF(I34>30000,2320+(I34-30000)*0.06)))) -> #VALUE! | W34: =IF(Q34=2,IF(U34<=10000,U34*0.09,IF(U34<=30000,900+(U34-10000)*0.08,IF(U34>30000,2500+(U34-30000)*0.06)))) -> #VALUE! | X34: =W34-V34 -> #VALUE!
I35: 0 | L35: =((0.15*H35)/12)*D35 -> 0 | M35: =E35*40 -> 0 | N35: =L35+M35 -> 0 | O35: =RIGHT(F35,2) | P35: =IF(ISNUMBER(O35),O35,VALUE(RIGHT(O35,2)&SUBSTITUTE(O35,RIGHT(O35,2),""))) -> #VALUE! | Q35: =IF(P35=99,1,2) -> #VALUE! | R35: 0 | T35: 0 | U35: =I35+R35 -> 0 | V35: =IF(Q35=2,IF(I35<=10000,I35*0.09,IF(I35<=30000,900+(I35-10000)*0.08,IF(I35>30000,2320+(I35-30000)*0.06)))) -> #VALUE! | W35: =IF(Q35=2,IF(U35<=10000,U35*0.09,IF(U35<=30000,900+(U35-10000)*0.08,IF(U35>30000,2500+(U35-30000)*0.06)))) -> #VALUE! | X35: =W35-V35 -> #VALUE!
I36: 0 | L36: =((0.15*H36)/12)*D36 -> 0 | M36: =E36*40 -> 0 | N36: =L36+M36 -> 0 | O36: =RIGHT(F36,2) | P36: =IF(ISNUMBER(O36),O36,VALUE(RIGHT(O36,2)&SUBSTITUTE(O36,RIGHT(O36,2),""))) -> #VALUE! | Q36: =IF(P36=99,1,2) -> #VALUE! | R36: 0 | T36: 0 | U36: =I36+R36 -> 0 | V36: =IF(Q36=2,IF(I36<=10000,I36*0.09,IF(I36<=30000,900+(I36-10000)*0.08,IF(I36>30000,2320+(I36-30000)*0.06)))) -> #VALUE! | W36: =IF(Q36=2,IF(U36<=10000,U36*0.09,IF(U36<=30000,900+(U36-10000)*0.08,IF(U36>30000,2500+(U36-30000)*0.06)))) -> #VALUE! | X36: =W36-V36 -> #VALUE!
... I49: 0 | L49: =((0.15*H49)/12)*D49 -> 0 | M49: =E49*40 -> 0 | N49: =L49+M49 -> 0 | O49: =RIGHT(F49,2) | P49: =IF(ISNUMBER(O49),O49,VALUE(RIGHT(O49,2)&SUBSTITUTE(O49,RIGHT(O49,2),""))) -> #VALUE! | Q49: =IF(P49=99,1,2) -> #VALUE! | R49: 0 | T49: 0 | U49: =I49+R49 -> 0 | V49: =IF(Q49=2,IF(I49<=10000,I49*0.09,IF(I49<=30000,900+(I49-10000)*0.08,IF(I49>30000,2320+(I49-30000)*0.06)))) -> #VALUE! | W49: =IF(Q49=2,IF(U49<=10000,U49*0.09,IF(U49<=30000,900+(U49-10000)*0.08,IF(U49>30000,2500+(U49-30000)*0.06)))) -> #VALUE! | X49: =W49-V49 -> #VALUE!
F50: =SUM(F16:F44) -> 20250336 | G50: =SUM(G16:G44) -> 0 | H50: =SUM(H16:H49) -> 69081.02 | I50: =SUM(I16:I49) -> 62000 | J50: =SUM(J16:J44) -> 0 | K50: =SUM(K16:K44) -> 0 | O50: =SUM(O16:O49) -> 0 | R50: =SUM(R16:R49) -> 14000 | T50: =SUM(T16:T49) -> 0 | U50: =SUM(U16:U49) -> 76000 | V50: =SUM(V16:V49) -> #VALUE! | W50: =SUM(W16:W49) -> #VALUE! | X50: =SUM(X16:X49) -> #VALUE!

Sheet Facture en préparation
E5: =Créances!H4 -> FT TRADING
E6: =Créances!H5 -> 108, Avenue Gallieni
E7: =Créances!H6 -> 93140 BONDY
D8: =IF(Créances!G7="","",IF(Créances!G7=0,"",Créances!G7)) | E8: =IF(Créances!H7="","",IF(Créances!H7=0,"",Créances!H7))
E9: =Créances!H8 -> Monsieur Hikmet AVINCA
C13: FACTURE No: | D13: 26000283
A15: =Créances!$A$13 -> Code Client : D93110
A16: L'Etat des encaissements reçus, commissions sur les encaissements et frais de procédure engagés pendant la période.
A17: V/REF | B17: N/REF | C17: Débiteur | D17: Encaissements | E17: Commissions | F17: Frais de procédure | G17: Lieu
A18: 1 | B18: 20250336 | C18: ALFA FOOD FACTORY | D18: 7000 | E18: 420 | F18: 0 | G18: AG
A29: LES ENCAISSEMENTS SELON LE LIEU
A30: A | B30: Encaissements Phénix (AG) | C30: =SUMIF(G17:G49,"AG",(D17:D81)) -> 7000
A31: B | B31: Encaissements Client (CL) | C31: =SUMIF(G17:G48,"CL",(D17:D80)) -> 0
A32: C=A+B | B32: Encaissements du mois: | C32: =C31+C30 -> 7000
A35: =IF(C40>0,"LES INFORMATIONS LIEES A LA FACTURE","LES INFORMATIONS LIEES A L'AVOIR") -> LES INFORMATIONS LIEES A LA FACTURE
A36: D | B36: COMMISSIONS HT | C36: =SUM(E18:E89) -> 420
A37: E | B37: FRAIS DE PROCEDURE HT | C37: =SUM(F18:F46) -> 0
A38: F=D+E | B38: TOTAL HT | C38: =C36+C37 -> 420
A39: G=F*20,00% | B39: TVA 20,00% | C39: =ROUND(C38*20%,2) -> 84
A40: H=F+G | B40: TOTAL TTC | C40: =SUM(C38:C39) -> 504
A43: LES INFORMATIONS LIEES AU VERSEMENT DES FONDS
A44: I=A-H | B44: =IF((C30-C40)>0,"Le solde des encaissements de la période est en votre faveur de :","Le solde des encaissements de la période est en notre faveur de :") -> Le solde des encaissements de la période est en votre faveur de : | C44: =IF(OR(AND(C32<0,C30<0),OR(C32<0,C30<0))," Le system ne peut gérer les sommes négatives, il faut établir un avoir manuel",IF((C30-C40)<0,C40-C30,(C30-C40))) -> 6496
A45: J | B45: =IF(C45=0,"Il n'y a pas de factures en retard de paiement ni d'avoirs en cours",IF(C45>0,"La somme des précédentes factures impayées :",IF(C45<0,"La sommes des avoirs en cours :"))) -> Il n'y a pas de factures en retard de paiement ni d'avoirs en cours | C45: 0
A46: K=I+J | B46: =IF((C30-C40-C45)>0,"Après prise en compte des précédentes factures et/ou avoirs, le solde comptable est en votre faveur de :","Après prise en compte des précédentes factures et/ou avoirs, le solde comptable est en notre faveur de :") -> Après prise en compte des précédentes factures et/ou avoirs, le solde comptable est en votre faveur de : | C46: =IF(AND(C30-C40>0,C45<0),(-1*C45)+C44,IF(AND(C30-C40>0,C44>C45),C44-C45,IF(AND(C30-C40>0,C44<C45),C45-C44,IF(AND(C30-C40<0,C45<0),IF(-1*C45>C44,(-1*C45)-C44,C44+(-1*C45)),IF(AND(C30-C40<0,C45>0),C44+C45,C44+C45))))) -> 6496
A49: EN CONCLUSION
A50: =IF((C30-C40-C45)>0,"Nous avons le plaisir de vous envoyer un règlement correspondant au solde comptable de :","Nous vous remercions de bien vouloir nous envoyer un règlement correspondant au solde comptable de :") -> Nous avons le plaisir de vous envoyer un règlement correspondant au solde comptable de : | C50: =+C46 -> 6496
A52: Pour tout règlement par virement bancaire | C52: RIB : 30004 02041 00010023074 93
C53: IBAN : FR76 3000 4020 4100 0100 2307 493
C54: BIC : BNPAFRPPEVY
A56: Mentions Obligatoires : Tout retard de paiement entraînera une pénalité, égale au dernier taux de refinancement de la BCE, majoré de 10 points, calculé au prorata temporis sur les sommes restant dues (art L441-6 Code de Commerce). Tout professionnel en situation de retard de paiement est de plein droit débiteur, à l’égard du créancier, d’une indemnité forfaitaire pour frais de recouvrement d’un montant minimum fixé à 40€ par facture (art. L441-6 et art D.441-5 du Code de Commerce).

Sheet Facture de vente
A12: Paris, le | B12: =TODAY() -> 46128
D16: =Créances!H4 -> FT TRADING
D17: =Créances!H8 -> Monsieur Hikmet AVINCA
D18: =Créances!H5 -> 108, Avenue Gallieni
D19: =IF(Créances!H6="","",IF(Créances!H6=0,"",Créances!H6)) -> 93140 BONDY
D20: =IF(Créances!H7="","",IF(Créances!H7=0,"",Créances!H7))
H22: Services | I22: Quantités | J22: Prix U HT
J23: 0
H24: Lettres de relance | I24: 1 | J24: 1
H25: Mandats de recouvrement | I25: 3 | J25: 2
H26: Rédaction de CGV | I26: 5 | J26: 3
H27: Journée de conseil | I27: 10 | J27: 4
H28: Siretisation | I28: 15 | J28: 5
I29: 20 | J29: 6
C30: FACTURE No: | D30: 1501023 | I30: 30 | J30: 7
I31: 60 | J31: 8
A32: =Créances!A13 -> Code Client : D93110 | I32: 100 | J32: 9
I33: 120 | J33: 10
B34: ACHAT : | C34: QUANTITE | D34: PRIX UNITAIRE HT | E34: TOTAL HT | I34: 200 | J34: 12
B35: Lettres de relances | E35: =IF(C35*D35=0,"",C35*D35) | H35: Règlement | I35: 250 | J35: 14
E36: =IF(C36*D36=0,"",C36*D36) | H36: Net à payer : | I36: 500 | J36: 15
E37: =IF(C37*D37=0,"",C37*D37) | H37: Facture réglée. | I37: 1000 | J37: 16
E38: =IF(C38*D38=0,"",C38*D38) | I38: 2500 | J38: 17
E39: =IF(C39*D39=0,"",C39*D39) | I39: 5000 | J39: 18
E40: =IF(C40*D40=0,"",C40*D40) | J40: 22
E41: =IF(C41*D41=0,"",C41*D41) | J41: 25
E42: =IF(C42*D42=0,"",C42*D42) | J42: 30
D43: TOTAL HT | E43: =SUM(E35:E42) -> 0 | J43: 35
D44: TVA 20% | E44: =E43*20% -> 0 | J44: 40
D45: TOTAL TTC | E45: =E43+E44 -> 0 | J45: 60
J46: 100
J47: 120
J48: 200
J49: 250
J50: 500
B51: =IF(C51="","","Déjà Réglé :") | J51: 300
B52: Net à payer : | C52: =IF(B51="Déjà Réglé :",E45-C51,IF(B52="Facture réglée.","",E45)) -> 0 | J52: 500
B53: =IF(B52="Facture réglée.","","Par virement ou par chèque à l'ordre du Cabinet Phénix." ) -> Par virement ou par chèque à l'ordre du Cabinet Phénix. | J53: 600
J54: 1000
J55: 1900
...

Sheet Facture de procedure
A14: Paris, le | B14: =TODAY() -> 46128
I17: Prix procedures
H18: Prestations | I18: 916.66666
D19: =Créances!H4 -> FT TRADING | I19: 50
D20: =Créances!H8 -> Monsieur Hikmet AVINCA | H20: Délivrance d'acte extra judiciaire | I20: 60
D21: =Créances!H5 -> 108, Avenue Gallieni | H21: Procédure en référé | I21: 70
D22: =IF(Créances!H6="","",IF(Créances!H6=0,"",Créances!H6)) -> 93140 BONDY | H22: Procédure au fond | I22: 75
D23: =IF(Créances!H7="","",IF(Créances!H7=0,"",Créances!H7)) | H23: Procédure d'exécution | I23: 75.25
I24: 76
I25: 77
I26: 78
I27: 79
H28: Règlement | I28: 80
H29: Net à payer : | I29: 85
C30: FACTURE No: | D30: 1502525 | H30: Facture réglée. | I30: 90
I31: 95
A32: =Créances!A13 -> Code Client : D93110 | I32: 100
H33: Nature de document | I33: 120
B34: PRESTATIONS | C34: Provision dans l'affaire contre | D34: HT | H34: FACTURE No: | I34: 150
B35: Délivrance d'acte extra judiciaire | D35: 5000 | H35: APPEL A PROVISION | I35: 180
I36: 200
I37: 250
I38: 300
I39: 350
I40: 400
I41: 450
I42: 500
C43: TOTAL HT | D43: =SUM(D35:D42) -> 5000 | I43: 600
C44: TVA 20% | D44: =D43*20% -> 1000 | I44: 700
C45: TOTAL TTC | D45: =D43+D44 -> 6000 | I45: 800
I46: 900
I47: 1000
I48: 1100
I49: 1200
I50: 1300
B51: =IF(C51="","","Déjà Réglé :") | I51: 1400
B52: Net à payer : | C52: =IF(B51="Déjà Réglé :",D45-C51,IF(B52="Facture réglée.","",D45)) -> 6000 | I52: 1500
B53: =IF(B52="Facture réglée.","","Par virement ou par chèque à l'ordre du Cabinet Phénix." ) -> Par virement ou par chèque à l'ordre du Cabinet Phénix. | I53: 1600
I54: 1700
I55: 1800
...

Sheet CI
A14: Paris, le | B14: =TODAY() -> 46128
D16: =Créances!H4 -> FT TRADING
D17: =Créances!H8 -> Monsieur Hikmet AVINCA
D18: =Créances!H5 -> 108, Avenue Gallieni
D19: =IF(Créances!H6="","",IF(Créances!H6=0,"",Créances!H6)) -> 93140 BONDY
D20: =IF(Créances!H7="","",IF(Créances!H7=0,"",Créances!H7))
H21: Date de la liquidation judiciaire
H22: Date du redressement judiciaire
H23: Date de la dissolution
H24: Date de la radiation du registre de commerce
C31: ATTESTATION D’IRRECOUVRABILITE | H31: Débiteur parti sans laisser d'adresse
H32: Modicité de la créance
H33: Insuffisance d'actif RJ
H34: Insuffisance d'actif LJ
H35: Insolvabilité du débiteur
A36: Pour motif : | B36: Défaut de réponse | H36: Forclusion LJ
A37: Références : | H37: Forclusion RJ | K37: Formules por le nom du débiteur | L37: Formules pour la somme restant due
H38: Défaut de provision | K38: =RIGHT(B37,6)
H39: Défaut de réponse | K39: =LEFT(K38,4)+16 -> #VALUE!
B40: Concernant le Débiteur | C40: Somme restant due | D40: Informations officielles | E40: Date de la dissolution | H40: Défaut de justificatifs | K40: Créances!G | L40: Créances!H
B41: =INDIRECT(CONCATENATE(K40,K39)) -> #VALUE! | C41: =INDIRECT(CONCATENATE(L40,K39)) - INDIRECT(CONCATENATE(L41,K39)) -> #VALUE! | L41: Créances!I
A43: =IF(B36="Débiteur parti sans laisser d'adresse",("Attendu que le débiteur cité ci-dessus est parti sans laisser d’adresse."),(IF(B36="Modicité de la créance",("Attendu que le débiteur cité ci-dessus n’exécute pas son obligation de payer votre créance, malgré diverses actions menées par notre Cabinet."),(IF(B36="Insuffisance d'actif RJ",("Attendu que le débiteur cité ci-dessus a été déclaré en redressement judiciaire."),(IF(B36="Insolvabilité du débiteur",("Attendu que votre débiteur cité ci-dessus ne réagit pas à nos multiples interventions."),(IF(B36="Forclusion LJ",("Attendu que le débiteur cité ci-dessus a été déclaré en liquidation judiciaire. "),(IF(B36="Forclusion RJ",("Attendu que le débiteur cité ci-dessus a été déclaré en redressement judiciaire. "),(IF(B36="Défaut de provision",("Attendu que votre débiteur ne réagit pas à nos multiples interventions, en sorte qu’il serait nécessaire de requérir judiciairement sa condamnation."),(IF(B36="Défaut de réponse",("Attendu que nous avons besoin de vos réponses pour défendre vos intérêts dans cette affaire."),(IF(B36="Défaut de justificatifs",("Attendu que vous ne produisez pas de pièces justifiant le bienfondé de votre créance."),(IF(B36="Insuffisance d'actif LJ",("Attendu que le débiteur cité ci-dessus a été déclaré en liquidation judiciaire.")))))))))))))))))))) -> Attendu que nous avons besoin de vos réponses pour défendre vos intérêts dans cette affaire.
A45: =IF(B36="Débiteur parti sans laisser d'adresse",("Attendu que les investigations pratiquées n’ont pas permis de localiser d’éventuels actifs saisissables lui appartenant."),(IF(B36="Modicité de la créance",("Attendu que la relative modicité de la somme restant due, ne permet pas raisonnablement d’exposer des frais judiciaires afin de requérir la condamnation du débiteur."),(IF(B36="Insuffisance d'actif RJ",("Attendu que les opérations de la procédure collective sont vouées à une clôture pour insuffisance d’actif."),(IF(B36="Insolvabilité du débiteur",("Attendu que les investigations pratiquées n’ont pas permis de révéler d’éventuels actifs saisissables lui appartenant, ce qui ne nous permet pas raisonnablement d’exposer des frais judiciaires."),(IF(B36="Forclusion LJ",("Attendu que les délais légaux pour déclarer votre créance ont expiré, votre créance est donc frappée de forclusion."),(IF(B36="Forclusion RJ",("Attendu que les délais légaux pour déclarer votre créance ont expiré, votre créance est donc frappée de forclusion."),(IF(B36="Défaut de provision",("Attendu qu’en l’état, à défaut d’engagement d’une procédure judiciaire, les voies de recouvrement à l’amiable ne peuvent pas aboutir dans ce dossier."),(IF(B36="Défaut de réponse",("Attendu que vous n’avez pas produit les éléments de réponse sollicités dans ce dossier, en sorte qu’il ne nous est pas possible de poursuivre une action de droit à l’encontre de votre débiteur."),(IF(B36="Défaut de justificatifs",("Compte tenu de l’absence de document signé ou revêtu du cachet commercial de votre débiteur, justifiant d’un lien de droit entre les parties, nous ne pouvons valablement envisager une voie de droit à son encontre (cf. article 1315 du Code civil)."),(IF(B36="Insuffisance d'actif LJ",("Attendu que les opérations de la procédure collective sont vouées à une clôture pour insuffisance d’actif.")))))))))))))))))))) -> Attendu que vous n’avez pas produit les éléments de réponse sollicités dans ce dossier, en sorte qu’il ne nous est pas possible de poursuivre une action de droit à l’encontre de votre débiteur.
A48: Le CABINET PHENIX atteste que votre créance est irrécouvrable et le présent certificat vous permet de passer votre créance en pertes et profits, conformément à la législation en vigueur.
B52: Débiteur : | C52: =B41 -> #VALUE!
B53: Pour une somme restant due de : | C53: =C41 -> #VALUE!
A56: Pour servir et valoir ce que de droit.
A60: Madame Perrine CLAVAUD
A61: Gérante

Sheet Etat Public
A12: ='Facture en préparation'!E5 -> FT TRADING
A13: ='Facture en préparation'!E6 -> 108, Avenue Gallieni
A14: ='Facture en préparation'!E7 -> 93140 BONDY
A15: ='Facture en préparation'!E8
A16: ='Facture en préparation'!E9 -> Monsieur Hikmet AVINCA
A19: ='Facture en préparation'!$A$15 -> Code Client : D93110
A20: NOMBRE | B20: V/REF | C20: REMIS LE | D20: ANCIENNETE | E20: N/REF | F20: DEBITEUR | G20: CREANCE PRINCIPALE | H20: RECOUVRE | I20: DONT EN ATTENTE DE FACTURATION | J20: ETAT | K20: CLOTURE
A21: 1 | B21: C0301 | C21: 40680 | D21: 7 | E21: 940058/000128 | F21: CREATION NATURE | G21: 29599.97 | H21: 8028.18 | I21: 4014.09 | J21: Gestion en cours | K21: (vide)

Sheet LettreN
A14: Paris, le | B14: =TODAY() -> 46128
E17: =INDIRECT(CONCATENATE(K44,K43)) -> 0
E18: 2, Rue Melingue
E19: 75019 PARIS | H19: =Créances!4:4 -> FT TRADING | I19: / | J19: =INDIRECT(CONCATENATE(K44,K43)) -> 0
A26: L1 | B26: =IF(A26="LR/AR","LETTRE DE MISE EN DEMEURE","") | I26: REGLES de saisies | K26: SAISIES cellules vertes
A27: N/Réf : | B27: 940012/000833 | G27: Types de Lettres | I27: Pénalité | J27: Indemnités | K27: Pénalité | L27: Indemnités
A28: Affaire : | B28: =CONCATENATE(H19, I19, J19) -> FT TRADING / 0 | G28: L1 | H28: Lettre avec pénalités et indemnités autos | I28: Auto | J28: Auto | K28: Auto | L28: Auto
G29: L2 | H29: Avec pénalités auto et ss indemnité | I29: Auto | J29: Sans | K29: Auto | L29: Sans
G30: L3 | H30: Avec pénalités manuel et ss indemnité | I30: Manuel | J30: Sans | L30: Sans
B31: Messieurs, | G31: L4 | H31: Avec pénalités et indemnites manuelles | I31: Manuel | J31: Manuel | K31: 200 | L31: 300
G32: LR/AR
B33: Notre client référencé ci-dessus nous confie la défense de ses intérêts au sujet de sa créance à votre
B34: encontre d’un montant de : | D34: =IF(A26="L1",F36+F37+F38,IF(A26="L2",F36+F37,IF(A26="L3",F36+F37,F36+F37+F38))) -> 0 | E34: se décomposant comme suit :
B36: Créance Principale : | F36: =INDIRECT(CONCATENATE(L44,K43)) -> 0
B37: Pénalités de retard : Tout retard de paiement entraînera une pénalité, égale au moins à trois fois le taux d'intérêt légal, calculé au prorata temporis sur les sommes restant dues (art. 441-6, I al. 12 du Code de Commerce). | F37: =IF(OR(A26="L1",A26="LR/AR"),INDIRECT(CONCATENATE(M44,K43)),IF(A26="L2",INDIRECT(CONCATENATE(M44,K43)),IF(A26="L3",K30,IF(A26="L4",K31)))) -> 0 | K37: Indemnités de recouvrement : Tout professionnel en situation de retard de paiement est de plein droit débiteur, à l’égard du créancier, d’une indemnité forfaitaire pour frais de recouvrement d’un montant minimum fixé à 40€ par facture (art. L441-6 et art. D.441-5 du Code de Commerce).
B38: =IF(OR(A26="L1",A26="LR/AR"),K37,IF(A26="L4",K37," ")) -> Indemnités de recouvrement : Tout professionnel en situation de retard de paiement est de plein droit débiteur, à l’égard du créancier, d’une indemnité forfaitaire pour frais de recouvrement d’un montant minimum fixé à 40€ par facture (art. L441-6 et art. D.441-5 du Code de Commerce). | F38: =IF(OR(A26="L1",A26="LR/AR"),INDIRECT(CONCATENATE(N44,K43)),IF(A26="L2"," ",IF(A26="L3"," ",IF(A26="L4",L31)))) -> 0
B40: =IF(A26="LR/AR", "Nous vous mettons en demeure de nous régler sous 8 jours francs la dite somme de","Nous vous demandons de nous faire parvenir sous 8 jours francs la dite somme de") -> Nous vous demandons de nous faire parvenir sous 8 jours francs la dite somme de | F40: =IF(A26="L1",F36+F37+F38,IF(A26="L2",F36+F37,IF(A26="L3",F36+K30,F36+F37+F38))) -> 0 | K40: FORMULES A NE PAS MODIFIER SVP
B41: à l'ordre du Cabinet Phénix, à défaut nous mettrons en œuvre toute voie de droit à votre encontre. | K41: Formules por le nom du débiteur | L41: Formules pour la somme restant due | M41: Formules pour pénalités | N41: Formules pour indemnités | O41: Formules pour total à réclamer
K42: =RIGHT(B27,6) -> 000833
B43: Le créancier qui justifie du caractère nécessaire des démarches entreprises pour recouvrer ses créances, peut demander au juge de l’exécution de laisser tout ou partie des frais ainsi exposés à la charge du débiteur de mauvaise foi. | K43: =LEFT(K42,4)+16 -> 24
K44: Créances!G | L44: Créances!H | M44: Créances!L | N44: Créances!M | O44: Créances!N
L45: Créances!I
B46: L’activité des personnes physiques ou morales non soumises à un statut professionnel qui, d’une manière habituelle ou occasionnelle, même à titre accessoire, procèdent au recouvrement amiable des créances pour le compte d’autrui, fait l’objet d’une réglementation fixée par décret en Conseil d’Etat.
B50: Veuillez agréer l’expression de nos salutations distinguées.
C53: "
D54: Merci de joindre le coupon réponse pour toute correspondance :
A56: Madame Perrine CLAVAUD | D56: N/Réf : | E56: =B27 -> 940012/000833
A57: Gérante | D57: Affaire : | E57: =CONCATENATE(H19, I19, J19) -> FT TRADING / 0
D58: IBAN : | E58: FR76 3000 4020 4100 0100 2452 993
D59: En cas de règlement par chèque à l'ordre du CABINET PHENIX :
D60: CABINET PHENIX
D61: 57, rue d'Amsterdam
D62: 75008 PARIS

Sheet LettreT
A14: Paris, le | B14: =TODAY() -> 46128
E16: =INDIRECT(CONCATENATE(K41,K40)) -> 0 | H16: =Créances!4:4 -> FT TRADING | I16: / | J16: =INDIRECT(CONCATENATE(K41,K40)) -> 0
E17: 34, Av. de la république
E18: 91230 MONTGERON
A23: L4 | B23: =IF(A23="LR/AR","LETTRE DE MISE EN DEMEURE","") | I23: REGLES de saisies | K23: SAISIES cellules vertes
A24: N/Réf : | B24: 940012/000713 | G24: Types de Lettres | I24: Pénalité | J24: Indemnités | K24: Pénalité | L24: Indemnités
A25: Affaire : | B25: =CONCATENATE(H16, I16, J16) -> FT TRADING / 0 | G25: L1 | H25: Lettre avec pénalités et indemnités autos | I25: Auto | J25: Auto | K25: Auto | L25: Auto
G26: L2 | H26: Avec pénalités auto et ss indemnité | I26: Auto | J26: Sans | K26: Auto | L26: Sans
G27: L3 | H27: Avec pénalités manuel et ss indemnité | I27: Manuel | J27: Sans | K27: 800 | L27: Sans
B28: Messieurs, | G28: L4 | H28: Avec pénalités et indemnites manuelles | I28: Manuel | J28: Manuel | K28: 200 | L28: 300
G29: LR/AR
B30: Notre client référencé ci-dessus nous confie la défense de ses intérêts au sujet de sa créance à votre
B31: encontre d’un montant de : | D31: =IF(A23="L1",F33+F34+F35,IF(A23="L2",F33+F34,IF(A23="L3",F33+F34,F33+F34+F35))) -> 500 | E31: se décomposant comme suit :
B33: Créance Principale : | F33: =INDIRECT(CONCATENATE(L41,K40)) -> 0
B34: Pénalités de retard : Tout retard de paiement entraînera une pénalité, égale au moins à trois fois le taux d'intérêt légal, calculé au prorata temporis sur les sommes restant dues (art. 441-6, I al. 12 du Code de Commerce). | F34: =IF(OR(A23="L1",A23="LR/AR"),INDIRECT(CONCATENATE(M41,K40)),IF(A23="L2",INDIRECT(CONCATENATE(M41,K40)),IF(A23="L3",K27,IF(A23="L4",K28)))) -> 200
B35: =IF(OR(A23="L1",A23="LR/AR"),K35,IF(A23="L4",K35," ")) -> Indemnités de recouvrement : Tout professionnel en situation de retard de paiement est de plein droit débiteur, à l’égard du créancier, d’une indemnité forfaitaire pour frais de recouvrement d’un montant minimum fixé à 40€ par facture (art. L441-6 et art. D.441-5 du Code de Commerce). | F35: =IF(OR(A23="L1",A23="LR/AR"),INDIRECT(CONCATENATE(N41,K40)),IF(A23="L2"," ",IF(A23="L3"," ",IF(A23="L4",L28)))) -> 300 | K35: Indemnités de recouvrement : Tout professionnel en situation de retard de paiement est de plein droit débiteur, à l’égard du créancier, d’une indemnité forfaitaire pour frais de recouvrement d’un montant minimum fixé à 40€ par facture (art. L441-6 et art. D.441-5 du Code de Commerce).
B37: =IF(A23="LR/AR", "Nous vous mettons en demeure de nous régler sous 8 jours francs la dite somme de","Nous vous demandons de nous faire parvenir sous 8 jours francs la dite somme de") -> Nous vous demandons de nous faire parvenir sous 8 jours francs la dite somme de | F37: =IF(A23="L1",F33+F34+F35,IF(A23="L2",F33+F34,IF(A23="L3",F33+K27,F33+F34+F35))) -> 500 | K37: FORMULES A NE PAS MODIFIER SVP
B38: à l'ordre du Cabinet Phénix, à défaut nous mettrons en œuvre toute voie de droit à votre encontre. | K38: Formules por le nom du débiteur | L38: Formules pour la somme restant due | M38: Formules pour pénalités | N38: Formules pour indemnités | O38: Formules pour total à réclamer
K39: =RIGHT(B24,6) -> 000713
B40: Le créancier qui justifie du caractère nécessaire des démarches entreprises pour recouvrer ses créances, peut demander au juge de l’exécution de laisser tout ou partie des frais ainsi exposés à la charge du débiteur de mauvaise foi. | K40: =LEFT(K39,4)+16 -> 23
K41: Créances!G | L41: Créances!H | M41: Créances!L | N41: Créances!M | O41: Créances!N
L42: Créances!I
B43: L’activité des personnes physiques ou morales non soumises à un statut professionnel qui, d’une manière habituelle ou occasionnelle, même à titre accessoire, procèdent au recouvrement amiable des créances pour le compte d’autrui, fait l’objet d’une réglementation fixée par décret en Conseil d’Etat.
B47: Veuillez agréer l’expression de nos salutations distinguées.
C51: "
D52: Merci de joindre le coupon réponse pour toute correspondance :
A53: Madame Perrine CLAVAUD
A54: Gérante | D54: N/Réf : | E54: =B24 -> 940012/000713
D55: Affaire : | E55: =B25 -> FT TRADING / 0
D56: IBAN : | E56: FR76 3000 4020 4100 0100 2452 993
D57: En cas de règlement par chèque à l'ordre du CABINET PHENIX :
D58: CABINET PHENIX
D59: 57, rue d'Amsterdam
D60: 75008 PARIS

Sheet Lettre2
A14: Paris, le | B14: =TODAY() -> 46128
E17: =INDIRECT(CONCATENATE(K44,K43)) -> 0
E18: 3, Squre Watteau
E19: 78330 FONTENAY LE FLEURY | H19: =Créances!4:4 -> FT TRADING | I19: / | J19: =INDIRECT(CONCATENATE(K44,K43)) -> 0
A27: N/Réf : | B27: 940012/015899
A28: Affaire : | B28: =CONCATENATE(H19, I19, J19) -> FT TRADING / 0
B31: Messieurs,
B33: Notre client référencé ci-dessus nous confie la défense de ses intérêts au sujet de sa créance à votre
B34: encontre d’un montant de : | D34: =F36+F37+F38 -> 0 | E34: se décomposant comme suit :
B36: Créance Principale : | F36: =INDIRECT(CONCATENATE(L44,K43)) -> 0
B37: Pénalités de retard : Tout retard de paiement entraînera une pénalité, égale au moins à trois fois le taux d'intérêt légal, calculé au prorata temporis sur les sommes restant dues (art. 441-6, I al. 12 du Code de Commerce). | F37: =INDIRECT(CONCATENATE(M44,K43)) -> 0
B38: Indemnités de recouvrement : Tout professionnel en situation de retard de paiement est de plein droit débiteur, à l’égard du créancier, d’une indemnité forfaitaire pour frais de recouvrement d’un montant minimum fixé à 40€ par facture (art. L441-6 et art. D.441-5 du Code de Commerce). | F38: =INDIRECT(CONCATENATE(N44,K43)) -> 0
B40: En cas de règlement directement à notre Cabinet dans les 8 jours francs suivant la réception de cette lettre, | K40: FORMULES A NE PAS MODIFIER SVP
B41: le montant à régler portera uniquement sur la dette principale de : | F41: =F36 -> 0 | K41: Formules por le nom du débiteur | L41: Formules pour la somme restant due | M41: Formules pour pénalités | N41: Formules pour indemnités | O41: Formules pour total à réclamer
K42: =RIGHT(B27,6) -> 015899
B43: Au-delà des 8 jours francs, le montant de votre dette principale sera donc majoré des pénalités et | K43: =LEFT(K42,4)+16 -> 174
B44: indemnités légales qui portera alors la somme due au montant de : | F44: =F36+F37+F38 -> 0 | K44: Créances!G | L44: Créances!H | M44: Créances!L | N44: Créances!M | O44: Créances!N
L45: Créances!I
B46: Le créancier qui justifie du caractère nécessaire des démarches entreprises pour recouvrer ses créances, peut demander au juge de l’exécution de laisser tout ou partie des frais ainsi exposés à la charge du débiteur de mauvaise foi.
B50: Veuillez agréer l’expression de nos salutations distinguées.
C52: "
D53: Merci de joindre le coupon réponse pour toute correspondance :
A55: Madame Perrine CLAVAUD | D55: N/Réf : | E55: =B27 -> 940012/015899
A56: Gérante | D56: Affaire : | E56: =B28 -> FT TRADING / 0
D57: IBAN : | E57: FR76 3000 4020 4100 0100 2452 993
D58: En cas de règlement par chèque à l'ordre du CABINET PHENIX :
D59: CABINET PHENIX
D60: 57, rue d'Amsterdam
D61: 75008 PARIS

Sheet Lettres Phénix
G5: =Créances!H4 -> FT TRADING
G6: =Créances!H5 -> 108, Avenue Gallieni
G7: =Créances!H6 -> 93140 BONDY
B9: Acheté | C9: Consommé | G9: =Créances!H8 -> Monsieur Hikmet AVINCA
A10: LR | B10: =Créances!$B$10 -> 0 | C10: =LARGE(A14:A1001,1) -> #NUM!
A13: NOMBRE | B13: DATE D'ENVOI | C13: Ancienneté en mois | D13: Nombre de factures | E13: DEBITEUR | F13: CREANCE TTC | G13: DATE DE MISE EN RECOUVREMENT CONSEILLE | H13: ETAT | I13: Adresse 1 | J13: Adresse 2 | K13: Code Postal | L13: Ville | M13: Pénalites
G14: =IF(B14="","",WORKDAY(B14,8,1)) | M14: =F14*(C14/100) -> 0
G15: =IF(B15="","",WORKDAY(B15,8,1)) | M15: =F15*(C15/100) -> 0
G16: =IF(B16="","",WORKDAY(B16,8,1)) | M16: =F16*(C16/100) -> 0
G17: =IF(B17="","",WORKDAY(B17,8,1)) | M17: =F17*(C17/100) -> 0
G18: =IF(B18="","",WORKDAY(B18,8,1)) | M18: =F18*(C18/100) -> 0
G19: =IF(B19="","",WORKDAY(B19,8,1)) | M19: =F19*(C19/100) -> 0
G20: =IF(B20="","",WORKDAY(B20,8,1)) | M20: =F20*(C20/100) -> 0
G21: =IF(B21="","",WORKDAY(B21,8,1)) | M21: =F21*(C21/100) -> 0
G22: =IF(B22="","",WORKDAY(B22,8,1)) | M22: =F22*(C22/100) -> 0
G23: =IF(B23="","",WORKDAY(B23,8,1)) | M23: =F23*(C23/100) -> 0
G24: =IF(B24="","",WORKDAY(B24,8,1)) | M24: =F24*(C24/100) -> 0
G25: =IF(B25="","",WORKDAY(B25,8,1)) | M25: =F25*(C25/100) -> 0
... G109: =IF(B109="","",WORKDAY(B109,8,1)) | M109: =F109*(C109/100) -> 0

Sheet Infos
